Workbook
Name _tv14: '[8]TE TS FA LAN MATV'!$F$89
Name Abab: [9]Bahan!$G$7
Name Bahan: [2]Bahan!$B$8:$E$1970
Name BahanSatuan: [2]Bahan!$C$8:$C$1970&[2]Bahan!$D$8:$D$1970
Name BahanSatuanA: [9]Bahan!$C$10:$C$701&[9]Bahan!$D$10:$D$701&[9]Bahan!$E$7
Name BahanSatuanB: [9]Bahan!$C$10:$C$701&[9]Bahan!$D$10:$D$701&[9]Bahan!$F$7
Name BahanSatuanC: [9]Bahan!$C$10:$C$701&[9]Bahan!$D$10:$D$701&[9]Bahan!$G$7
Name BahanSatuanD: [9]Bahan!$C$10:$C$701&[9]Bahan!$D$10:$D$701&[9]Bahan!$H$7
Name BahanSatuanE: [9]Bahan!$C$10:$C$701&[9]Bahan!$D$10:$D$701&[9]Bahan!$I$7
Name Harga_Alat: '[14]HSD ALAT'!$C$6:$K$5003
Name Harga_Bahan: '[14]HSD BAHAN'!$C$6:$J$5001
Name Harga_Upah: '[14]HSD UPAH'!$B$6:$E$5000
Name Jenis_Alat: '[14]HSD ALAT'!$H$6:$H$5003
Name Jenis_Bahan: '[14]HSD BAHAN'!$H$6:$H$5001
Name Jenis_Upah: '[14]HSD UPAH'!$C$6:$C$5000
Name jnrtrjn: '[16]Analisa 23'!$H$35
Name Kode_Alat: '[14]HSD ALAT'!$C$6:$C$5003
Name Kode_Bahan: '[14]HSD BAHAN'!$C$6:$C$5001
Name Kode_Upah: '[14]HSD UPAH'!$B$6:$B$5000
Name Penukal: [9]Bahan!$H$7
Name PenukalUtara: [9]Bahan!$I$7
Name Profit: '[2]Analisa 23'!$H$35
Name TalangUbi: [9]Bahan!$E$7
Name TanahAbang: [9]Bahan!$F$7
Name Upah: [2]Upah!$B$10:$E$82
Name UpahSatuan: [2]Upah!$C$10:$C$82&[2]Upah!$D$10:$D$82

Sheet Rekap
A2: REKAPITULASI ANGGARAN
A3: =+[1]NOTE!B4 -> Kegiatan | F3: : Penyelenggaraan Bangunan Gedung Di Wilayah Daerah Kabupaten/Kota
A4: =+[1]NOTE!B5 -> Pekerjaan | F4: : Perencanaan Kantor Kelurahan Sambaliung Kab. Berau
A5: =+[1]NOTE!B6 -> Lokasi | F5: : Kab. Berau
A7: NO. | B7: URAIAN PEKERJAAN | I7: JUMLAH HARGA (Rp.)
A10: A | E10: =RAB!D11 -> KANTOR KELURAHAN SAMBALIUNG
A11: I | E11: =RAB!D12 -> PENYELENGGARAAN SMKK | I11: =RAB!K36 -> 50900000
A12: II | E12: =RAB!D37 -> PEKERJAAN PENDAHULUAN | I12: =RAB!K44 -> 1.0683061e+08
A13: III | E13: =RAB!D45 -> PEKERJAAN TANAH | I13: =RAB!K51 -> 1.0311496e+08
A14: IV | E14: =RAB!D52 -> PEKERJAAN STRUKTUR | I14: =RAB!K167 -> 2.0468165e+09
A15: V | E15: =RAB!D168 -> PEKERJAAN STRUKTUR ATAP | I15: =RAB!K182 -> 4.7193832e+08
A16: VI | E16: =RAB!D183 -> PEKERJAAN ARSITEKTUR | I16: =RAB!K189 -> 2.5366943e+08
A17: VII | E17: =RAB!D190 -> PEKERJAAN PLUMBING | I17: =RAB!K194 -> 19225680
B19: JUMLAH SELURUH PEKERJAAN | I19: =SUM(I11:I18) -> 3.0524955e+09
B20: PPN 11% | I20: =I19*0.11 -> 3.357745e+08
B21: JUMLAH SELURUH PEKERJAAN + PPN | I21: =I19+I20 -> 3.38827e+09
B22: PEMBULATAN | I22: =ROUNDUP(I21,-3) -> 3388270000
A23: TERBILANG :
E24: Tiga Miliar Tiga Ratus Delapan Puluh Delapan Juta Dua Ratus Tujuh Puluh Ribu Rupiah
A26: `+
H28: Berau, 22 Juli 2024
H29: Dibuat oleh,
H30: Konsultan Perencana
H31: PT. Rumah Kutai Perencana
H36: Wahyullah Bandung, ST
H37: Direktur
B39: Diketahui Oleh | H39: Disetujui Oleh
B40: PLT. Kepala Dinas Pekerjaan Umum | H40: Kuasa Pengguna Anggaran dan
H41: Kepala Bidang Gedung Pemerintah
H42: Dinas Pekerjaan Umum Kota Balikpapan

Sheet RAB
A1: RENCANA ANGGARAN BIAYA ( RAB )
A3: =+'[1]Contoh Rekap RAB'!A3:D3 -> Kegiatan | G3: =Rekap!F3 -> : Penyelenggaraan Bangunan Gedung Di Wilayah Daerah Kabupaten/Kota
A4: =+'[1]Contoh Rekap RAB'!A4:D4 -> Pekerjaan | G4: =Rekap!F4 -> : Perencanaan Kantor Kelurahan Sambaliung Kab. Berau
A5: =+'[1]Contoh Rekap RAB'!A5:D5 -> Lokasi | G5: =Rekap!F5 -> : Kab. Berau
A7: KODE | B7: NO. | C7: URAIAN PEKERJAAAN | H7: SAT. | I7: VOLUME | J7: HARGA SAT. | K7: JUMLAH HARGA
A8: SNI | J8: (Rp.) | K8: (Rp.)
A9: 1 | B9: 2 | C9: 3 | H9: 4 | I9: 5 | J9: 6 | K9: 7
B11: A | D11: KANTOR KELURAHAN SAMBALIUNG
B12: I | D12: PENYELENGGARAAN SMKK
B13: 1 | D13: Penyiapan Dokumen K3 | H13: Ls | I13: =BV!O15 -> 1 | J13: ='[2]K3 Gedung'!K18 -> 1500000 | K13: =I13*J13 -> 1500000
B14: =B13+1 -> 2 | D14: Sosialisasi, Promosi, dan Pelatihan:
D15: Induksi Keselamatan Konstruksi (Safety Induction) | H15: Org | I15: =BV!O17 -> 25 | J15: ='[2]K3 Gedung'!J21 -> 100000 | K15: =I15*J15 -> 2500000
D16: Pengarahan Keselamatan Konstruksi (Safety Briefing) | H16: Org | I16: =BV!O18 -> 25 | J16: ='[2]K3 Gedung'!J22 -> 100000 | K16: =I16*J16 -> 2500000
D17: Pertemuan keselamatan (Safety Talk dan/atau Tool Box Meeting) | H17: Org | I17: =BV!O19 -> 25 | J17: ='[2]K3 Gedung'!J23 -> 100000 | K17: =I17*J17 -> 2500000
B18: 3 | D18: Alat Pelindung Kerja dan Alat Pelindung Diri
D19: Topi Pelindung (Safety Helmet) | H19: Bh | I19: =BV!O21 -> 25 | J19: ='[2]K3 Gedung'!J48 -> 50000 | K19: =I19*J19 -> 1250000
D20: Sarung Tangan (Safety Gloves) | H20: Psg | I20: =BV!O22 -> 25 | J20: ='[2]K3 Gedung'!J54 -> 15000 | K20: =I20*J20 -> 375000
D21: Sepatu Keselamatan (Safety Shoes, Rubber Safety Shoes and Toe Cap) | H21: Psg | I21: =BV!O23 -> 25 | J21: ='[2]K3 Gedung'!J55 -> 200000 | K21: =I21*J21 -> 5000000
D22: Rompi keselamatan (Safety Vest) | H22: Bh | I22: =BV!O24 -> 25 | J22: ='[2]K3 Gedung'!J58 -> 140000 | K22: =I22*J22 -> 3500000
B23: 4 | D23: Asuransi dan Perizinan Terkait Keselamatan Konstruksi: | H23: Ls | I23: =BV!O25 -> 1 | J23: ='[2]K3 Gedung'!J64 -> 22500000 | K23: =I23*J23 -> 22500000
B24: 5 | D24: Personel Keselamatan Konstruksi :
D25: Petugas K3 Konstruksi | H25: Org | I25: =BV!O27 -> 1 | J25: ='[2]K3 Gedung'!J72 -> 5000000 | K25: =I25*J25 -> 5000000
B26: 6 | D26: Fasilitas, Sarana dan Prasarana Kesehatan:
D27: Peralatan P3K | H27: Bh | I27: =BV!O29 -> 1 | J27: ='[2]K3 Gedung'!J81 -> 500000 | K27: =I27*J27 -> 500000
B28: 7 | D28: Rambu dan Perlengkapan Lalu Lintas yang Diperlukan atau Manajemen lalu lintas:
D29: Rambu Petunjuk | H29: Bh | I29: =BV!O31 -> 3 | J29: ='[2]K3 Gedung'!J91 -> 75000 | K29: =I29*J29 -> 225000
D30: Rambu Larangan | H30: Bh | I30: =BV!O32 -> 3 | J30: ='[2]K3 Gedung'!J92 -> 75000 | K30: =I30*J30 -> 225000
D31: Rambu Peringatan | H31: Bh | I31: =BV!O33 -> 3 | J31: ='[2]K3 Gedung'!J93 -> 75000 | K31: =I31*J31 -> 225000
B32: 8 | D32: Konsultasi dengan Ahli terkait Keselamatan Konstruksi:
D33: Ahli Struktur | H33: Oj/Ok | I33: ='[2]K3 Gedung'!I113 -> 3 | J33: ='[2]K3 Gedung'!J113 -> 1000000 | K33: =I33*J33 -> 3000000
B34: 9 | D34: Lain- Lain Terkait Pengendalian Risiko Keselamatan Konstruksi:
D35: Bendera K3 | H35: Bh | I35: =BV!O36 -> 1 | J35: ='[2]K3 Gedung'!J132 -> 100000 | K35: =I35*J35 -> 100000
H36: Jumlah I | K36: =SUM(K13:K35) -> 50900000
B37: II | D37: PEKERJAAN PENDAHULUAN
B38: 1 | D38: Pembersihan Lapangan | H38: m² | I38: =BV!O41 -> 384 | J38: =[2]AHSP!D32 -> 17985 | K38: =I38*J38 -> 6906240
B39: 2 | D39: Pembongkaran Bangunan Eksisting | H39: m³ | I39: =BV!O40 -> 57.6 | J39: =[2]AHSP!D193 -> 107289.6 | K39: =I39*J39 -> 6179881
B40: 3 | D40: Pemasangan Papan Proyek | H40: Bh | I40: =BV!O42 -> 1 | J40: =[2]AHSP!D24 -> 605764.5 | K40: =I40*J40 -> 605764.5
B41: 4 | D41: Pemasangan Pagar Sementara | H41: m¹ | I41: =BV!O43 -> 81.2 | J41: =[2]AHSP!D15 -> 470311.64 | K41: =I41*J41 -> 38189305
B42: 5 | D42: Pembuatan Kantor Direksi Keet | H42: m² | I42: =BV!O46 -> 16 | J42: =[2]AHSP!D26 -> 2525219.2 | K42: =I42*J42 -> 40403507
B43: 6 | D43: Pengukuran dan Pemasangan Bowplank | H43: m¹ | I43: =BV!O47 -> 218 | J43: =[2]AHSP!D52 -> 66724.35 | K43: =I43*J43 -> 14545908
...

Sheet BV
A1: BACKUP VOLUME
A4: Kegiatan | E4: =Rekap!F3 -> : Penyelenggaraan Bangunan Gedung Di Wilayah Daerah Kabupaten/Kota
A5: Pekerjaan | E5: =Rekap!F4 -> : Perencanaan Kantor Kelurahan Sambaliung Kab. Berau
A6: Lokasi | E6: =Rekap!F5 -> : Kab. Berau
A9: NO. | B9: URAIAN KEGIATAN | F9: PANJANG | G9: LEBAR | H9: TINGGI | I9: TITIK | J9: JUMLAH | K9: KOEF. | L9: LUAS | M9: LUAS 2 | N9: SAT. | O9: VOLUME
A10: 1 | B10: 2 | F10: 3 | G10: 4 | H10: 5 | I10: 6 | J10: 7 | K10: 8 | L10: 9 | M10: 10 | N10: 11 | O10: 12
A13: A | C13: KELURAHAN SAMBALIUNG
A14: I | C14: PENYELENGGARAAN SMKK
A15: 1 | C15: Penyiapan RKK, RKPPL, dan RMLLP | J15: 1 | N15: Ls | O15: =J15 -> 1
A16: 2 | C16: Sosialisasi, Promosi, dan Pelatihan:
C17: Induksi Keselamatan Konstruksi (Safety Induction) | J17: 25 | N17: Org | O17: =J17 -> 25
C18: Pengarahan Keselamatan Konstruksi (Safety Briefing) | J18: 25 | N18: Org | O18: =J18 -> 25
C19: Pertemuan keselamatan (Safety Talk dan/atau Tool Box Meeting) | J19: 25 | N19: Org | O19: =J19 -> 25
A20: 3 | C20: Alat Pelindung Kerja dan Alat Pelindung Diri
C21: Topi Pelindung (Safety Helmet) | J21: 25 | N21: Bh | O21: =J21 -> 25
C22: Sarung Tangan (Safety Gloves) | J22: 25 | N22: Psg | O22: =J22 -> 25
C23: Sepatu Keselamatan (Safety Shoes, Rubber Safety Shoes and Toe Cap) | J23: 25 | N23: Psg | O23: =J23 -> 25
C24: Rompi keselamatan (Safety Vest) | J24: 25 | N24: Bh | O24: =J24 -> 25
A25: 4 | C25: Asuransi dan Perizinan Terkait Keselamatan Konstruksi: | J25: 1 | N25: Ls | O25: =J25 -> 1
A26: 5 | C26: Personel Keselamatan Konstruksi :
C27: Petugas K3 Konstruksi | J27: 1 | N27: Org | O27: =J27 -> 1
A28: 6 | C28: Fasilitas, Sarana dan Prasarana Kesehatan:
C29: Peralatan P3K | J29: 1 | N29: Bh | O29: =J29 -> 1
A30: 7 | C30: Rambu dan Perlengkapan Lalu Lintas yang Diperlukan atau Manajemen lalu lintas:
C31: Rambu Petunjuk | J31: 3 | N31: Bh | O31: =J31 -> 3
C32: Rambu Larangan | J32: 3 | N32: Bh | O32: =J32 -> 3
C33: Rambu Peringatan | J33: 3 | N33: Bh | O33: =J33 -> 3
A34: 8 | C34: Konsultasi dengan Ahli terkait Keselamatan Konstruksi: | J34: 1 | N34: Ls | O34: =J34 -> 1
A35: 9 | C35: Lain- Lain Terkait Pengendalian Risiko Keselamatan Konstruksi:
C36: Bendera K3 | J36: 1 | N36: Bh | O36: =J36 -> 1
A39: II | C39: PEKERJAAN PENDAHULUAN
A40: 1 | C40: Pembongkaran Eksisting | F40: =F41 -> 25.6 | G40: =G41 -> 15 | J40: 0.15 | N40: M3 | O40: =F40*G40*J40 -> 57.6
A41: 2 | C41: Pembersihan Lapangan | F41: 25.6 | G41: 15 | N41: m² | O41: =F41*G41 -> 384
A42: 3 | C42: Pemasangan Papan Proyek | J42: 1 | N42: Bh | O42: =J42 -> 1
A43: 4 | C43: Pemasangan Pagar Sementara | F43: =(F41+G41)*2 -> 81.2 | N43: m¹ | O43: =F43 -> 81.2
A46: 5 | C46: Pembuatan Kantor Direksi Keet | F46: 4 | G46: 4 | N46: m² | O46: =F46*G46 -> 16
A47: 6 | C47: Pengukuran dan Pemasangan Bowplank | F47: =(25.6*5)+(15*6) -> 218 | N47: m¹ | O47: =F47 -> 218
A50: III | C50: PEKERJAAN TANAH
A51: 1 | C51: Galian Tanah
C52: Galian Tanah Pondasi P1 | F52: 0.6 | G52: 0.6 | H52: 1.8 | J52: 2 | N52: m³ | O52: =F52*G52*H52*J52 -> 1.296
...
