Workbook
Name _: #REF!
Name _____________________________DIV11: #REF!
Name _____________________________EEE02: #REF!
Name _____________________________EEE05: #REF!
Name _____________________________EEE06: #REF!
Name _____________________________EEE07: #REF!
Name _____________________________EEE08: #REF!
Name _____________________________EEE09: #REF!
Name _____________________________EEE10: #REF!
Name _____________________________EEE11: #REF!
Name _____________________________EEE13: #REF!
Name _____________________________EEE15: #REF!
Name _____________________________EEE16: #REF!
Name _____________________________EEE17: #REF!
Name _____________________________EEE22: #REF!
Name _____________________________EEE23: #REF!
Name _____________________________EEE27: #REF!
Name _____________________________EEE29: #REF!
Name _____________________________MMM19: #REF!
Name ____________________________DIV11: #REF!
Name ____________________________EEE02: #REF!
Name ____________________________EEE05: #REF!
Name ____________________________EEE06: #REF!
Name ____________________________EEE07: #REF!
Name ____________________________EEE08: #REF!
Name ____________________________EEE09: #REF!
Name ____________________________EEE10: #REF!
Name ____________________________EEE11: #REF!
Name ____________________________EEE13: #REF!
Name ____________________________EEE15: #REF!
Name ____________________________EEE16: #REF!
Name ____________________________EEE17: #REF!
Name ____________________________EEE19: #REF!
Name ____________________________EEE22: #REF!
Name ____________________________EEE23: #REF!
Name ____________________________EEE27: #REF!
Name ____________________________EEE29: #REF!
Name ____________________________EEE31: #REF!
Name ____________________________MMM19: #REF!
Name ___________________________DIV1: #REF!
Name ___________________________DIV10: #REF!
Name ___________________________DIV11: #REF!
Name ___________________________DIV2: #REF!
Name ___________________________DIV5: #REF!
Name ___________________________DIV7: #REF!
Name ___________________________DIV8: #REF!
Name ___________________________DIV9: #REF!
Name ___________________________EEE02: #REF!
Name ___________________________EEE05: #REF!
Name ___________________________EEE06: #REF!
Name ___________________________EEE07: #REF!
Name ___________________________EEE08: #REF!
Name ___________________________EEE09: #REF!
Name ___________________________EEE10: #REF!
Name ___________________________EEE11: #REF!
Name ___________________________EEE13: #REF!
Name ___________________________EEE15: #REF!
Name ___________________________EEE16: #REF!
Name ___________________________EEE17: #REF!
Name ___________________________EEE19: #REF!

Sheet UPAH
A1: UPAH PEKERJA
A4: No. | B4: Tenaga Kerja | G4: Kode | H4: Satuan | I4: Harga Satuan (Rp.) | K4: Keterangan | M4: Jam Kerja Eff. | N4: 8
A6: 1 | C6: Pekerja | G6: L.01 | H6: OH | I6: =TRUNC(J6/$N$4,-2) -> 22000 | J6: 176000
A7: =A6+1 -> 2 | C7: Pekerja Anyam | G7: L.01 | H7: OH | I7: =TRUNC(J7/$N$4,-2) -> 22000 | J7: 176000
A8: 3 | C8: Pekerja Pengisi Batu | G8: L.01 | H8: OH | I8: =TRUNC(J8/$N$4,-2) -> 22000 | J8: 176000
A9: =A8+1 -> 4 | C9: Tukang | G9: L.02 | H9: OH | I9: =TRUNC(J9/$N$4,-2) -> 23200 | J9: 186000
A10: 5 | C10: Tukang Gali | G10: L.02 | H10: OH | I10: =TRUNC(J10/$N$4,-2) -> 23200 | J10: 186000
A11: =A10+1 -> 6 | C11: Tukang Batu | G11: L.02 | H11: OH | I11: =TRUNC(J11/$N$4,-2) -> 23200 | J11: 186000
A12: 7 | C12: Tukang Kayu | G12: L.02 | H12: OH | I12: =TRUNC(J12/$N$4,-2) -> 23200 | J12: 186000
A13: =A12+1 -> 8 | C13: Tukang Besi | G13: L.02 | H13: OH | I13: =TRUNC(J13/$N$4,-2) -> 23200 | J13: 186000
A14: 9 | C14: Tukang Besi Konstruksi | G14: L.02 | H14: OH | I14: =TRUNC(J14/$N$4,-2) -> 23200 | J14: 186000
A15: =A14+1 -> 10 | C15: Tukang Alumunium | G15: L.02 | H15: OH | I15: =TRUNC(J15/$N$4,-2) -> 23200 | J15: 186000
A16: 11 | C16: Tukang pelitur | G16: L.02 | H16: OH | I16: =TRUNC(J16/$N$4,-2) -> 23200 | J16: 186000
A17: =A16+1 -> 12 | C17: Tukang Cat | G17: L.02 | H17: OH | I17: =TRUNC(J17/$N$4,-2) -> 23200 | J17: 186000
A18: 13 | C18: Tukang Pipa | G18: L.02 | H18: OH | I18: =TRUNC(J18/$N$4,-2) -> 23200 | J18: 186000
A19: =A18+1 -> 14 | C19: Tukang Pengayam Bronjong | G19: L.02 | H19: OH | I19: =TRUNC(J19/$N$4,-2) -> 23200 | J19: 186000
A20: 15 | C20: Tukang Tebas | G20: L.02 | H20: OH | I20: =TRUNC(J20/$N$4,-2) -> 23200 | J20: 186000
A21: =A20+1 -> 16 | C21: Tukang Vibrator | G21: L.02 | H21: OH | I21: =TRUNC(J21/$N$4,-2) -> 23200 | J21: 186000
A22: 17 | C22: Tukang Listrik | G22: L.02 | H22: OH | I22: =TRUNC(J22/$N$4,-2) -> 23200 | J22: 186000
A23: =A22+1 -> 18 | C23: Tukang Ereksi | G23: L.02 | H23: OH | I23: =TRUNC(J23/$N$4,-2) -> 23200 | J23: 186000
A24: 19 | C24: Tukang Las | G24: L.02 | H24: OH | I24: =TRUNC(J24/$N$4,-2) -> 23200 | J24: 186000
A25: =A24+1 -> 20 | C25: Tukang Las Konstruksi | G25: L.02 | H25: OH | I25: =TRUNC(J25/$N$4,-2) -> 23200 | J25: 186000
A26: 11 | C26: Tukang penganyam bronjong | G26: L.02 | H26: OH | I26: =TRUNC(J26/$N$4,-2) -> 23200 | J26: 186000
A27: 21 | C27: Kepala Tukang | G27: L.03 | H27: OH | I27: =TRUNC(J27/$N$4,-2) -> 24500 | J27: 196000
A28: 22 | C28: Mandor | G28: L.04 | H28: OH | I28: =TRUNC(J28/$N$4,-2) -> 25700 | J28: =J9+20000 -> 206000
A29: 23 | C29: Juru Ukur | G29: L.05 | H29: OH | I29: =TRUNC(J29/$N$4,-2) -> 27000 | J29: 216000
A30: 24 | C30: Pembantu Juru Ukur | G30: L.06 | H30: OH | I30: =TRUNC(J30/$N$4,-2) -> 25700 | J30: 206000
A31: =A30+1 -> 25 | C31: Ahli Alat Berat ( Mekanik ) | G31: L.07 | H31: OH | I31: =TRUNC(J31/$N$4,-2) -> 27000 | J31: 216000
A32: 26 | C32: Operator Alat Berat | G32: L.08 | H32: OH | I32: =TRUNC(J32/$N$4,-2) -> 27000 | J32: 216000
A33: =A32+1 -> 27 | C33: Pembantu Operator | G33: L.09 | H33: OH | I33: =TRUNC(J33/$N$4,-2) -> 27000 | J33: 216000
A34: 28 | C34: Operator Alat Pipa | G34: L.08 | H34: OH | I34: =TRUNC(J34/$N$4,-2) -> 27000 | J34: 216000
A35: =A34+1 -> 29 | C35: Sopir Truck | G35: L.10 | H35: OH | I35: =TRUNC(J35/$N$4,-2) -> 27000 | J35: 216000
A36: 30 | C36: Kenek Truk | G36: L.11 | H36: OH | I36: =TRUNC(J36/$N$4,-2) -> 27000 | J36: 216000
A37: 31 | C37: Penjaga Malam | G37: L.12 | H37: OH | I37: =TRUNC(J37/$N$4,-2) -> 27000 | J37: 216000
A38: 32 | C38: Juru Gambar (Drafter) | G38: L.13 | H38: OH | I38: =TRUNC(J38/$N$4,-2) -> 27000 | J38: 216000
A39: 33 | C39: Design Engineer | G39: L.15 | H39: OH | I39: =TRUNC(J39/$N$4,-2) -> 27000 | J39: 216000
A40: 34 | C40: Operator Printer/Plotter | G40: L.16 | H40: OH | I40: =TRUNC(J40/$N$4,-2) -> 27000 | J40: 216000
A41: 35 | C41: Operator crane | G41: L.08 | H41: OH | I41: =TRUNC(J41/$N$4,-2) -> 27000 | J41: 216000
A42: 36 | C42: Pembantu operator crane | G42: L.09 | H42: OH | I42: =TRUNC(J42/$N$4,-2) -> 27000 | J42: 216000
A43: =A42+1 -> 37 | C43: Bor Master | H43: OH | I43: =TRUNC(J43/$N$4,-2) -> 27000 | J43: 216000
...

Sheet BAHAN
A1: HARGA BAHAN ZONA 3
A4: No. | B4: HARGA BAHAN | F4: Satuan | G4: Harga Satuan | H4: Keterangan
A6: 1 | B6: Air | F6: Liter | G6: 100
A7: 2 | B7: Air Kerja | F7: Liter | G7: 100
A8: 3 | B8: Air test (air bersih) | F8: m3 | G8: 0
A9: 4 | B9: Air Bersih / PDAM | F9: Liter | G9: 0
A10: 5 | B10: Akustik 60 x 120 | F10: Lembar | G10: 200000
A11: 6 | B11: Akustik ukuran 30 x 30 cm | F11: Lembar | G11: 150000
A12: 7 | B12: Akustik ukuran 30 x 60 cm | F12: Lembar | G12: 130000
A13: 8 | B13: Alang-alang | F13: Ikat | G13: 1000
A14: 9 | B14: Aluminium Composite Panel | F14: Lbr | G14: 750000
A15: 10 | B15: Aluminium strip | F15: m | G15: 80000
A16: 11 | B16: Alumunium foil | F16: M2 | G16: 53200
A17: 12 | B17: Alumunium gel tbl 0,55 | F17: Lbr | G17: 647800
... A20: 15 | B20: Asbes gelombang 92x200 | F20: Lbr | G20: 76300
A21: 16 | B21: Atap metal | F21: lbr | G21: 148400 | H21: =G21/(0.75*6) -> 32977.778
A22: 17 | B22: Atap metal menerus | F22: lbr | G22: 207300 | H22: =G22/(0.75*6) -> 46066.667
A23: 18 | B23: Assesoris (perkuatan, las dll) | F23: Ls | G23: 50000
A24: 19 | B24: Bahan bakar | F24: liter | G24: 15000
A25: 20 | B25: Bahan tambahan kimia | F25: Liter | G25: 0
A26: 21 | B26: Baut baja | F26: kg | G26: 100000
A27: 22 | B27: Baja ringan canai dingin C75 | F27: M' | G27: 145000
A28: 23 | B28: Baja Ringan C75, t=0,75 mm | F28: M' | G28: 90000
A29: 24 | B29: Baja strip (0,2 x 2) cm | F29: kg | G29: 30200
A30: 25 | B30: Baja tulangan | F30: Kg | G30: 22000
A31: 26 | B31: Bak cuci piring | F31: Unit | G31: 450000
A32: 27 | B32: Bak fibreglass | F32: Unit | G32: 453300
A33: 28 | B33: Balok kayu kelas I | F33: m3 | G33: 6800000
A34: 29 | B34: Balok kayu kelas II | F34: m3 | G34: 5500000
... A46: 41 | B46: Batu granit | F46: Kg | G46: 0
A47: 42 | B47: Batu paras Dinding | F47: Bh | G47: 11880 | I47: =(0.2*0.1)*50 -> 1 | J47: 594000 | K47: =J47/50 -> 11880
A48: 43 | B48: Batu pecah | F48: m3 | G48: 900000
A49: 44 | B49: Batu traso | F49: Kg | G49: 0
A50: 45 | B50: Baut (Srew driver) | F50: bh | G50: 500
A51: 46 | B51: beton K-275 ready mix | F51: m3 | G51: 1935000
A52: 47 | B52: Beton Ready Mixed f'c 15 MPa | F52: m3 | G52: 1855000
A53: 48 | B53: Beton Ready Mixed f'c 17 MPa | F53: m3 | G53: 1865000
A54: 49 | B54: Beton Ready Mixed f'c 20 MPa | F54: m3 | G54: 1890000
A55: 50 | B55: Beton Ready Mixed f'c 21 MPa | F55: m3 | G55: 1897500
A56: 51 | B56: Beton Ready Mixed f'c 25 MPa | F56: m3 | G56: 1935000
...

Sheet Rekap HSP
A1: REKAPTULASI ANALISA HARGA SATUAN PEKERJAAN
A3: Kegiatan
A4: Sub Kegiatan
A5: Pekerjaan
A6: Lokasi
A7: Tahun Anggaran
A9: Kode Analisa | B9: Jenis Pekerjaan | E9: Vol | F9: Satuan | G9: Harga Satuan (RP)
A12: U.1.1.1 (c) | B12: Pembuatan 1 m' pagar sementara dari kayu tinggi 2 m | E12: 1 | F12: m' | G12: 748339.5
A14: U.1.1.2 (c) | B14: Pembuatan 1 m' pagar sementara dari seng gelombang rangka kayu tinggi 2 m | E14: 1 | F14: m' | G14: 535929
A16: U.1.2.1.d (a) | B16: Pasangan 1 m' bouwplank | E16: 1 | F16: m' | G16: 107946.45
A18: U.3.4.1.a.1 (c) | B18: Penggalian 1 m3 tanah biasa sedalam s.d 1 m untuk volume s.d. 200 m3 cara manual | E18: 1 | F18: m3 | G18: 140652.6
A20: U.3.4.1.a.4 (a) | B20: Penggalian 1 m3 tanah biasa sedalam lebih dari 1 m s.d 2 m untuk volume s.d. 200 m3 cara manual | E20: 1 | F20: m3 | G20: 168646.5
A22: U.3.5.1.a (c) | B22: 1 m3 Urugan kembali galian tanah (> 0 s.d. 200 m3), tanpa pemadatan secara manual | E22: 1 | F22: m3 | G22: 93692.5
A24: U.3.5.1.b (c) | B24: 1 m3 Timbunan dengan pasir urug (> 0 s.d. 200 m3), tanpa pemadatan secara manual | E24: 1 | F24: m3 | G24: 320215.5
A26: U.3.5.1.d (a) | B26: 1 m3 Urugan tanah biasa, tanpa pemadatan secara manual | E26: 1 | F26: m3 | G26: 126005
A28: U.3.5.2.a (c) | B28: 1 m3 Pemadatan tanah per 20 cm menggunakan alat timbris secara manual | E28: 1 | F28: m3 | G28: 93692.5
A30: U.3.5.3.a (a) | B30: 1 m3 Pemadatan Tanah setebal 10 cm secara semi-mekanis | E30: 1 | F30: m3 | G30: 29645
A32: A.3.2.1.1 | B32: Pemasangan 1 m3 pondasi batu belah campuran 1SP : 3PP | E32: 1 | F32: m3 | G32: 1730154.2
A34: A.3.2.1.2 | B34: Pemasangan 1 m3 pondasi batu belah campuran 1SP : 4PP | E34: 1 | F34: m3 | G34: 1662779.2
... A46: A.4.1.1.6 | B46: Membuat 1 m3 beton f'c = 16,9 Mpa (setara beton K 200) | E46: 1 | F46: m3 | G46: 1987444.7
A48: =AHSP!B8 -> A.1.1.1.1 | B48: =AHSP!C8 -> Pembuatan 1 m’ pagar sementara dari kayu tinggi 2 meter | E48: 1 | F48: m' | G48: =AHSP!I31 -> 754783 | I48: +
A50: =AHSP!B33 -> A.1.1.1.2 | B50: =AHSP!C33 -> Pembuatan 1 m’ pagar sementara dari seng gelombang rangka kayu tinggi 2 meter | E50: 1 | F50: m' | G50: =AHSP!I55 -> 466733
A52: =AHSP!B57 -> A.1.1.1.3 | B52: =AHSP!C57 -> Pembuatan 1 m2 pagar sementara dari kawat duri tinggi 2 meter | E52: 1 | F52: m2 | G52: =AHSP!I79 -> 953925
A54: =AHSP!C81 -> 1.1.1.6 | B54: =AHSP!D81 -> Pemasangan 1 m2 panel beton pracetak 50x50x240 untuk pagar | E54: 1 | F54: m2 | G54: =AHSP!I100 -> 102739.12
A56: =AHSP!C103 -> 1.1.2.1 | B56: =AHSP!D103 -> 1 buah papan nama pekerjaan ukuran 0.8x1.2 menggunakan multiflex 18 mm, frame besi siku dan tiang kayu 8/12 | E56: 1 | F56: unit | G56: =AHSP!I123 -> 749329.6
A58: =AHSP!C126 -> 1.1.2.2 | B58: =AHSP!D126 -> 1 buah papan nama pekerjaan ukuran 0.6x08 menggunakan multiplex 10 mm, frame allumunium siku dan tiang kayu 5/7, printing banner plastik | E58: 1 | F58: unit | G58: =AHSP!I146 -> 337207.51 | I58: +
A60: =AHSP!C149 -> 1.1.2.3 | B60: =AHSP!D149 -> Pembuatan 1 m2 kantor sementara/rumah jaga/gudang semen dan peralatan lantai plesteran, dinding setengah tembok | E60: 1 | F60: unit | G60: =AHSP!I178 -> 2285963.9
A62: =AHSP!C181 -> 1.1.2.4 | B62: =AHSP!D181 -> Pembuatan 1 m2 direksi keet (Kantor), los kerja dan gudang | E62: 1 | F62: unit | G62: =AHSP!I206 -> 1964226 | I62: +
A64: =AHSP!C209 -> 1.1.2.5 | B64: =AHSP!D209 -> Pembuatan 1 m2 jalan sementara lapis macadam | E64: 1 | F64: m2 | G64: =AHSP!I231 -> 422683.39
A66: =AHSP!C234 -> 1.1.2.6 | B66: =AHSP!D234 -> Pembuatan 1 m2 jalan sementara (Jalan Tanah) | E66: 1 | F66: m2 | G66: =AHSP!I246 -> 0
A68: =AHSP!C249 -> 1.1.2.7 | B68: =AHSP!D249 -> Pembuatan 1 m2 jalan sementara (Jalan Kerikil) | E68: 1 | F68: m2 | G68: =AHSP!I262 -> 0
A70: =AHSP!C265 -> 1.1.3.1 | B70: =AHSP!D265 -> 1 m3 Pembersihan dan pengupasan permukaan tanah (striping) s.d. tanaman ∅ 2 cm | E70: 1 | F70: m3 | G70: =AHSP!I277 -> 20493
A72: =AHSP!C279 -> 1.1.3.3. | B72: =AHSP!D279 -> Tebas tebang 1 m 2 tanaman/tumbuhan ∅ >5 s.d. 15 cm | E72: 1 | F72: m2 | G72: =AHSP!I291 -> 10813
A74: =AHSP!C293 -> 1.1.3.4 | B74: =AHSP!D293 -> Tebas tebang 1 batang pohon/tumbuhan ∅ >15 s.d. 30 cm | E74: 1 | F74: btg | G74: =AHSP!I306 -> 17300.839
A76: =AHSP!C308 -> 1.1.3.5 | B76: =AHSP!D308 -> Tebas tebang 1 batang pohon/tumbuhan ∅ > 30 s.d 50 cm | E76: 1 | F76: btg | G76: =AHSP!I321 -> 2595.1887
A78: =AHSP!C323 -> 1.1.3.6 | B78: =AHSP!D323 -> Tebas tebang 1 batang pohon/tumbuhan ∅ > 50 s.d 75 cm (diameter pohon diukur 1 m di atas permukaan tanah) | E78: 1 | F78: btg | G78: =AHSP!I336 -> 36764.288
A80: =AHSP!C338 -> 1.1.3.7 | B80: =AHSP!D338 -> Tebas tebang 1 batang pohon/tumbuhan ∅ > 75 cm (diameter pohon diukur 1 m di atas permukaan tanah) | E80: 1 | F80: btg | G80: =AHSP!I351 -> 54065.099
A82: =AHSP!C353 -> 1.1.3.8 | B82: =AHSP!D353 -> Gali dan cabut 1 tunggul pohon tanaman keras ∅ > 5 s.d. 15 cm (termasuk pembuangan sisa tunggul tanpa menutup kembali bekas lubang) | E82: 1 | F82: btg | G82: =AHSP!I366 -> 30905.919
A84: =AHSP!C368 -> 1.1.3.9 | B84: =AHSP!D368 -> Gali dan cabut 1 tunggul pohon tanaman keras ∅ > 15 cm s.d. 30 cm (termasuk pembuangan sisa tunggul tanpa menutup kembali bekas lubang) | E84: 1 | F84: btg | G84: =AHSP!I381 -> 36235.034
A86: =AHSP!C383 -> 1.1.3.10 | B86: =AHSP!D383 -> Gali dan cabut 1 tunggul pohon tanaman keras ∅ > 30 cm s.d. 50 cm (termasuk pembuangan sisa tunggul tanpa menutup kembali bekas lubang) | E86: 1 | F86: btg | G86: =AHSP!I396 -> 39456.362
...

Sheet AHSP
A1: AHSP (Analisa Harga Satuan Pekerjaan)
L3: PROFIT | M3: 0.1
C4: ANALISA HARGA SATUAN PEKERJAAN (AHSP)
A7: A.2.2.1 | B7: HARGA SATUAN PEKERJAAN PERSIAPAN
B8: A.1.1.1.1 | C8: Pembuatan 1 m’ pagar sementara dari kayu tinggi 2 meter | J8: =I31 -> 754783
C9: No | D9: Uraian | E9: Kode | F9: Satuan | G9: Koefisien | H9: Harga Satuan (Rp.) | I9: Jumlah Harga (Rp.)
C10: A | D10: TENAGA
D11: Pekerja | E11: L.01 | F11: OH | G11: 0.6 | H11: 176000 | I11: =G11*H11 -> 105600
D12: Tukang Kayu | E12: L.02 | F12: OH | G12: 0.2 | H12: 186000 | I12: =G12*H12 -> 37200
D13: Tukang Batu | E13: L.02 | F13: OH | G13: 0.2 | H13: 186000 | I13: =G13*H13 -> 37200
D14: Kepala Tukang | E14: L.03 | F14: OH | G14: 0.04 | H14: 196000 | I14: =G14*H14 -> 7840
D15: Mandor | E15: L.04 | F15: OH | G15: 0.013 | H15: 206000 | I15: =G15*H15 -> 2678
G16: JUMLAH TENAGA KERJA | I16: =SUM(I11:I15) -> 190518
C17: B | D17: BAHAN
D18: Kayu kaso 5/7 | F18: m3 | G18: 0.0387 | H18: =VLOOKUP(D18,BAHAN!B6:G546,6,FALSE) -> 3950000 | I18: =G18*H18 -> 152865
D19: Kayu papan 3/20 | F19: m3 | G19: 0.0396 | H19: =VLOOKUP(D19,BAHAN!B7:G547,6,FALSE) -> 5500000 | I19: =G19*H19 -> 217800
D20: Paku biasa 2” - 5” | F20: kg | G20: 0.5872 | H20: =VLOOKUP(D20,BAHAN!B8:G548,6,FALSE) -> 22000 | I20: =G20*H20 -> 12918.4
D21: Semen portland | F21: kg | G21: 26.406 | H21: =VLOOKUP(D21,BAHAN!B9:G550,6,FALSE) -> 1820 | I21: =G21*H21 -> 48058.92
D22: Pasir beton kg | F22: kg | G22: 61.56 | H22: =VLOOKUP(D22,BAHAN!B10:G551,6,FALSE) -> 474.42857 | I22: =G22*H22 -> 29205.823
D23: Kerikil kg | F23: kg | G23: 83.349 | H23: =VLOOKUP(D23,BAHAN!B11:G552,6,FALSE) -> 396.63704 | I23: =G23*H23 -> 33059.3
D24: Air | F24: liter | G24: 17.415 | H24: =BAHAN!G6 -> 100 | I24: =G24*H24 -> 1741.5
D25: Residu | F25: liter | G25: 0.4 | H25: =VLOOKUP(D25,BAHAN!B13:G554,6,FALSE) -> 57600 | I25: =G25*H25 -> 23040
G26: JUMLAH HARGA BAHAN | I26: =SUM(I17:I24) -> 495648.94
C27: C | D27: PERALATAN
G28: JUMLAH HARGA ALAT | I28: =I27 -> 0
C29: D | D29: Jumlah (A+B+C) | I29: =I16+I26+I28 -> 686166.94
C30: E | D30: Overhead & Profit 10% | G30: =$M$3 -> 0.1 | I30: =G30*I29 -> 68616.694
C31: F | D31: Harga Satuan Pekerjaan (D+E) | H31: 0 | I31: =ROUNDDOWN(I29+I30,0) -> 754783
B33: A.1.1.1.2 | C33: Pembuatan 1 m’ pagar sementara dari seng gelombang rangka kayu tinggi 2 meter | J33: =I55 -> 466733
C34: No | D34: Uraian | E34: Kode | F34: Satuan | G34: Koefisien | H34: Harga Satuan (Rp.) | I34: Jumlah Harga (Rp.)
C35: A | D35: TENAGA | H35: 0 | I35: =G35*H35 -> 0
D36: Pekerja | E36: L.01 | F36: OH | G36: 0.25 | H36: 176000 | I36: =G36*H36 -> 44000
D37: Tukang Kayu | E37: L.02 | F37: OH | G37: 0.125 | H37: 186000 | I37: =G37*H37 -> 23250
D38: Tukang Batu | E38: L.02 | F38: OH | G38: 0.125 | H38: 186000 | I38: =G38*H38 -> 23250
D39: Kepala Tukang | E39: L.03 | F39: OH | G39: 0.025 | H39: 196000 | I39: =G39*H39 -> 4900
D40: Mandor | E40: L.04 | F40: OH | G40: 0.008 | H40: 206000 | I40: =G40*H40 -> 1648
G41: JUMLAH TENAGA KERJA | I41: =SUM(I35:I40) -> 97048
C42: B | D42: BAHAN
D43: Kayu kaso 5/7 | F43: m3 | G43: 0.031 | H43: =VLOOKUP(D43,BAHAN!B33:G570,6,FALSE) -> 3950000 | I43: =G43*H43 -> 122450
D44: Seng gelombang | F44: lembar | G44: 1.3125 | H44: =VLOOKUP(D44,BAHAN!B34:G571,6,FALSE) -> 63500 | I44: =G44*H44 -> 83343.75
...
